Workbook

Sheet Torquiose Pendant
B1: PRODUCT PRICE WORKSHEET
B4: Section:
B5: Pendant
B7: Product name:
B8: Torquiose Pendant
B10: SKU:
B11: ='SKU Generator'!F4 -> PEN-POL-TOR-28
B15: MATERIAL COSTS
B16: Material (metric) | C16: Material Price | D16: Quantity | E16: Total Material Price | F16: Vendors
B18: Polymer Clay | C18: 2 | D18: 1 | E18: =C18*D18 -> 2
B19: Wood Beads | C19: 1 | D19: 1 | E19: =C19*D19 -> 1
B20: Findings | C20: 0.5 | D20: 1 | E20: =C20*D20 -> 0.5
B21: Faux Suede thread | C21: 0.1 | D21: 1 | E21: =C21*D21 -> 0.1
E22: =C22*D22 -> 0
E23: =C23*D23 -> 0
E24: =C24*D24 -> 0
B25: Sub-total | E25: =SUM(E18:E24) -> 3.6
B27: LABOR COSTS
B28: Labor | C28: Number of hours | D28: Hourly Wage | E28: Total Labor | F28: Notes
B30: Don | D30: 10 | E30: =C30*D30 -> 0
B31: Sherrie | C31: 1 | D31: 10 | E31: =C31*D31 -> 10
E32: =C32*D32 -> 0
E33: =C33*D33 -> 0
E34: =C34*D34 -> 0
E35: =C35*D35 -> 0
B36: Sub-total | E36: =SUM(E30:E35) -> 10
B38: PACKAGING COSTS
B39: Packaging | C39: Qty | D39: Cost | E39: Total Packaging | F39: Notes
B41: Box | C41: 1 | D41: 3 | E41: =C41*D41 -> 3
E42: =C42*D42 -> 0
E43: =C43*D43 -> 0
E44: =C44*D44 -> 0
E45: =C45*D45 -> 0
E46: =C46*D46 -> 0
B47: Sub-total | E47: =SUM(E41:E46) -> 3
B49: OTHER COSTS
B50: Description | C50: Qty | D50: Cost | E50: Total Other Costs | F50: Notes
E52: =C52*D52 -> 0
E53: =C53*D53 -> 0
B54: Sub-total | E54: =SUM(E48:E53) -> 0
...

Sheet Aztec Princess
B1: PRODUCT PRICE WORKSHEET
B4: Section:
B5: Pendant
B7: Product name:
B8: Torquiose Pendant
B10: SKU:
B11: ='SKU Generator'!F4 -> PEN-POL-TOR-28
B15: MATERIAL COSTS
B16: Material (metric) | C16: Material Price | D16: Quantity | E16: Total Material Price | F16: Vendors
E18: =C18*D18 -> 0
E19: =C19*D19 -> 0
E20: =C20*D20 -> 0
E21: =C21*D21 -> 0
E22: =C22*D22 -> 0
E23: =C23*D23 -> 0
E24: =C24*D24 -> 0
B25: Sub-total | E25: =SUM(E18:E24) -> 0
B27: LABOR COSTS
B28: Labor | C28: Number of hours | D28: Hourly Wage | E28: Total Labor | F28: Notes
E30: =C30*D30 -> 0
E31: =C31*D31 -> 0
E32: =C32*D32 -> 0
E33: =C33*D33 -> 0
E34: =C34*D34 -> 0
E35: =C35*D35 -> 0
B36: Sub-total | E36: =SUM(E30:E35) -> 0
B38: PACKAGING COSTS
B39: Packaging | C39: Qty | D39: Cost | E39: Total Packaging | F39: Notes
E41: =C41*D41 -> 0
E42: =C42*D42 -> 0
E43: =C43*D43 -> 0
E44: =C44*D44 -> 0
E45: =C45*D45 -> 0
E46: =C46*D46 -> 0
B47: Sub-total | E47: =SUM(E41:E46) -> 0
B49: OTHER COSTS
B50: Description | C50: Qty | D50: Cost | E50: Total Other Costs | F50: Notes
E52: =C52*D52 -> 0
E53: =C53*D53 -> 0
B54: Sub-total | E54: =SUM(E48:E53) -> 0
...

Sheet SKU Generator
B2: Product name | C2: Medium | D2: Color | E2: Size | F2: SKU
C3: Type | D3: [Example: Color] | E3: [Insert option] | F3: Automatic
B4: Pendant | C4: Polymer Clay | D4: Torquiose | E4: 28 | F4: =TRIM(UPPER(LEFT(B4,3)))&IF(ISBLANK(C4),"","-")&TRIM(UPPER(LEFT(C4,3)))&IF(ISBLANK(D4),"","-")&TRIM(UPPER(LEFT(D4,3)))&IF(ISBLANK(E4),"","-")&TRIM(UPPER(LEFT(E4,3))) -> PEN-POL-TOR-28
B5: Bracelet | C5: Polymer Clay | D5: Native American | E5: Regular | F5: =TRIM(UPPER(LEFT(B5,3)))&IF(ISBLANK(C5),"","-")&TRIM(UPPER(LEFT(C5,3)))&IF(ISBLANK(D5),"","-")&TRIM(UPPER(LEFT(D5,3)))&IF(ISBLANK(E5),"","-")&TRIM(UPPER(LEFT(E5,3))) -> BRA-POL-NAT-REG
B6: Bracelet | C6: Polymer Clay | D6: Native American | E6: XL | F6: =TRIM(UPPER(LEFT(B6,3)))&IF(ISBLANK(C6),"","-")&TRIM(UPPER(LEFT(C6,3)))&IF(ISBLANK(D6),"","-")&TRIM(UPPER(LEFT(D6,3)))&IF(ISBLANK(E6),"","-")&TRIM(UPPER(LEFT(E6,3))) -> BRA-POL-NAT-XL
B7: Earrings | C7: Polymer Clay | D7: Native American | F7: =TRIM(UPPER(LEFT(B7,3)))&IF(ISBLANK(C7),"","-")&TRIM(UPPER(LEFT(C7,3)))&IF(ISBLANK(D7),"","-")&TRIM(UPPER(LEFT(D7,3)))&IF(ISBLANK(E7),"","-")&TRIM(UPPER(LEFT(E7,3))) -> EAR-POL-NAT
B8: Aztec Princess | C8: Polymer Clay | D8: Silver/Blue | E8: Adjustable | F8: =TRIM(UPPER(LEFT(B8,3)))&IF(ISBLANK(C8),"","-")&TRIM(UPPER(LEFT(C8,3)))&IF(ISBLANK(D8),"","-")&TRIM(UPPER(LEFT(D8,3)))&IF(ISBLANK(E8),"","-")&TRIM(UPPER(LEFT(E8,3))) -> AZT-POL-SIL-ADJ
B9: Boho Style | C9: Polymer Clay | D9: Brown | E9: dangle | F9: =TRIM(UPPER(LEFT(B9,3)))&IF(ISBLANK(C9),"","-")&TRIM(UPPER(LEFT(C9,3)))&IF(ISBLANK(D9),"","-")&TRIM(UPPER(LEFT(D9,3)))&IF(ISBLANK(E9),"","-")&TRIM(UPPER(LEFT(E9,3))) -> BOH-POL-BRO-DAN
B10: Pendant | C10: Polymer Clay | D10: Pink | E10: 22 | F10: =TRIM(UPPER(LEFT(B10,3)))&IF(ISBLANK(C10),"","-")&TRIM(UPPER(LEFT(C10,3)))&IF(ISBLANK(D10),"","-")&TRIM(UPPER(LEFT(D10,3)))&IF(ISBLANK(E10),"","-")&TRIM(UPPER(LEFT(E10,3))) -> PEN-POL-PIN-22
B11: Set | C11: Polymer Clay | D11: Multi Colored | E11: 22 | F11: =TRIM(UPPER(LEFT(B11,3)))&IF(ISBLANK(C11),"","-")&TRIM(UPPER(LEFT(C11,3)))&IF(ISBLANK(D11),"","-")&TRIM(UPPER(LEFT(D11,3)))&IF(ISBLANK(E11),"","-")&TRIM(UPPER(LEFT(E11,3))) -> SET-POL-MUL-22
B12: Turquoise Heart Pendant | C12: Polymer Clay | D12: Blue/Silver | E12: 22 | F12: =TRIM(UPPER(LEFT(B12,3)))&IF(ISBLANK(C12),"","-")&TRIM(UPPER(LEFT(C12,3)))&IF(ISBLANK(D12),"","-")&TRIM(UPPER(LEFT(D12,3)))&IF(ISBLANK(E12),"","-")&TRIM(UPPER(LEFT(E12,3))) -> TUR-POL-BLU-22
B13: Oval Pendant | C13: Polymer Clay | D13: Multi Colored | E13: 22 | F13: =TRIM(UPPER(LEFT(B13,3)))&IF(ISBLANK(C13),"","-")&TRIM(UPPER(LEFT(C13,3)))&IF(ISBLANK(D13),"","-")&TRIM(UPPER(LEFT(D13,3)))&IF(ISBLANK(E13),"","-")&TRIM(UPPER(LEFT(E13,3))) -> OVA-POL-MUL-22
B14: Oval Earrings | C14: Polymer Clay | D14: Multi Colored | E14: dangle | F14: =TRIM(UPPER(LEFT(B14,3)))&IF(ISBLANK(C14),"","-")&TRIM(UPPER(LEFT(C14,3)))&IF(ISBLANK(D14),"","-")&TRIM(UPPER(LEFT(D14,3)))&IF(ISBLANK(E14),"","-")&TRIM(UPPER(LEFT(E14,3))) -> OVA-POL-MUL-DAN
B15: Beaded Necklace & Earrings | C15: Polymer Clay | D15: Multi Colored | E15: 18 | F15: =TRIM(UPPER(LEFT(B15,3)))&IF(ISBLANK(C15),"","-")&TRIM(UPPER(LEFT(C15,3)))&IF(ISBLANK(D15),"","-")&TRIM(UPPER(LEFT(D15,3)))&IF(ISBLANK(E15),"","-")&TRIM(UPPER(LEFT(E15,3))) -> BEA-POL-MUL-18
B16: Glass Beaded Necklace | C16: Polymer Clay | D16: Lavender | E16: 28 | F16: =TRIM(UPPER(LEFT(B16,3)))&IF(ISBLANK(C16),"","-")&TRIM(UPPER(LEFT(C16,3)))&IF(ISBLANK(D16),"","-")&TRIM(UPPER(LEFT(D16,3)))&IF(ISBLANK(E16),"","-")&TRIM(UPPER(LEFT(E16,3))) -> GLA-POL-LAV-28
B17: Pearlized Beaded Necklace | C17: Polymer Clay | D17: Pastel | E17: 18 | F17: =TRIM(UPPER(LEFT(B17,3)))&IF(ISBLANK(C17),"","-")&TRIM(UPPER(LEFT(C17,3)))&IF(ISBLANK(D17),"","-")&TRIM(UPPER(LEFT(D17,3)))&IF(ISBLANK(E17),"","-")&TRIM(UPPER(LEFT(E17,3))) -> PEA-POL-PAS-18
B18: Turquoise Bracelet | C18: Polymer Clay | D18: Blue/Silver | E18: Cuff | F18: =TRIM(UPPER(LEFT(B18,3)))&IF(ISBLANK(C18),"","-")&TRIM(UPPER(LEFT(C18,3)))&IF(ISBLANK(D18),"","-")&TRIM(UPPER(LEFT(D18,3)))&IF(ISBLANK(E18),"","-")&TRIM(UPPER(LEFT(E18,3))) -> TUR-POL-BLU-CUF
B19: Earrings & Pendant Set | C19: Polymer Clay | D19: Mica Powder | E19: Set | F19: =TRIM(UPPER(LEFT(B19,3)))&IF(ISBLANK(C19),"","-")&TRIM(UPPER(LEFT(C19,3)))&IF(ISBLANK(D19),"","-")&TRIM(UPPER(LEFT(D19,3)))&IF(ISBLANK(E19),"","-")&TRIM(UPPER(LEFT(E19,3))) -> EAR-POL-MIC-SET
B20: Earrings & Pendant Set | C20: Polymer Clay | D20: Mica Powder | E20: Set | F20: =TRIM(UPPER(LEFT(B20,3)))&IF(ISBLANK(C20),"","-")&TRIM(UPPER(LEFT(C20,3)))&IF(ISBLANK(D20),"","-")&TRIM(UPPER(LEFT(D20,3)))&IF(ISBLANK(E20),"","-")&TRIM(UPPER(LEFT(E20,3))) -> EAR-POL-MIC-SET
B21: Earrings | C21: Resin | D21: Clear | E21: Pair | F21: =TRIM(UPPER(LEFT(B21,3)))&IF(ISBLANK(C21),"","-")&TRIM(UPPER(LEFT(C21,3)))&IF(ISBLANK(D21),"","-")&TRIM(UPPER(LEFT(D21,3)))&IF(ISBLANK(E21),"","-")&TRIM(UPPER(LEFT(E21,3))) -> EAR-RES-CLE-PAI
B22: Earrings | C22: Resin | D22: Black | E22: Pair | F22: =TRIM(UPPER(LEFT(B22,3)))&IF(ISBLANK(C22),"","-")&TRIM(UPPER(LEFT(C22,3)))&IF(ISBLANK(D22),"","-")&TRIM(UPPER(LEFT(D22,3)))&IF(ISBLANK(E22),"","-")&TRIM(UPPER(LEFT(E22,3))) -> EAR-RES-BLA-PAI
F23: =TRIM(UPPER(LEFT(B23,3)))&IF(ISBLANK(C23),"","-")&TRIM(UPPER(LEFT(C23,3)))&IF(ISBLANK(D23),"","-")&TRIM(UPPER(LEFT(D23,3)))&IF(ISBLANK(E23),"","-")&TRIM(UPPER(LEFT(E23,3)))
F24: =TRIM(UPPER(LEFT(B24,3)))&IF(ISBLANK(C24),"","-")&TRIM(UPPER(LEFT(C24,3)))&IF(ISBLANK(D24),"","-")&TRIM(UPPER(LEFT(D24,3)))&IF(ISBLANK(E24),"","-")&TRIM(UPPER(LEFT(E24,3)))
F25: =TRIM(UPPER(LEFT(B25,3)))&IF(ISBLANK(C25),"","-")&TRIM(UPPER(LEFT(C25,3)))&IF(ISBLANK(D25),"","-")&TRIM(UPPER(LEFT(D25,3)))&IF(ISBLANK(E25),"","-")&TRIM(UPPER(LEFT(E25,3)))
F26: =TRIM(UPPER(LEFT(B26,3)))&IF(ISBLANK(C26),"","-")&TRIM(UPPER(LEFT(C26,3)))&IF(ISBLANK(D26),"","-")&TRIM(UPPER(LEFT(D26,3)))&IF(ISBLANK(E26),"","-")&TRIM(UPPER(LEFT(E26,3)))
F27: =TRIM(UPPER(LEFT(B27,3)))&IF(ISBLANK(C27),"","-")&TRIM(UPPER(LEFT(C27,3)))&IF(ISBLANK(D27),"","-")&TRIM(UPPER(LEFT(D27,3)))&IF(ISBLANK(E27),"","-")&TRIM(UPPER(LEFT(E27,3)))
F28: =TRIM(UPPER(LEFT(B28,3)))&IF(ISBLANK(C28),"","-")&TRIM(UPPER(LEFT(C28,3)))&IF(ISBLANK(D28),"","-")&TRIM(UPPER(LEFT(D28,3)))&IF(ISBLANK(E28),"","-")&TRIM(UPPER(LEFT(E28,3)))
F29: =TRIM(UPPER(LEFT(B29,3)))&IF(ISBLANK(C29),"","-")&TRIM(UPPER(LEFT(C29,3)))&IF(ISBLANK(D29),"","-")&TRIM(UPPER(LEFT(D29,3)))&IF(ISBLANK(E29),"","-")&TRIM(UPPER(LEFT(E29,3)))

Sheet Clean_Data
A1: Product_Name | B1: Quantity | C1: Material_ Cost | D1: Labor_Cost | E1: Packing_Cost | F1: Shipping_Cost | G1: Fees | H1: Tax | I1: Total_Cost | J1: Selling_Price | K1: Profit | L1: Profit_Margin | M1: Quantity_Sold | N1: Total_Revenue
A2: Pendant01 | B2: 1 | C2: 3.6 | D2: 10 | E2: 3 | F2: 2.5 | G2: 5 | H2: =SUM(C2:F2)*0.09 -> 1.719 | I2: =SUM(C2:H2)*B2 -> 25.819 | J2: =I2*(1+Dashboard!$I$1) -> 33.5647 | K2: =J2-I2 -> 7.7457 | L2: =K2/J2 -> 0.23076923 | M2: =SUM(B:B) -> 5 | N2: =J2*B2 -> 33.5647
A3: Earrings01 | B3: 1 | C3: 1.1 | D3: 3 | E3: 3 | F3: 2.5 | G3: 5 | H3: =SUM(C3:F3)*0.09 -> 0.864 | I3: =SUM(C3:H3)*B3 -> 15.464 | J3: =I3*(1+Dashboard!$I$1) -> 20.1032 | K3: =J3-I3 -> 4.6392 | L3: =K3/J3 -> 0.23076923 | N3: =J3*B3 -> 20.1032
A4: Bracelet01 | B4: 1 | C4: 2.1 | D4: 5 | E4: 3 | F4: 2.5 | G4: 5 | H4: =SUM(C4:F4)*0.09 -> 1.134 | I4: =SUM(C4:H4)*B4 -> 18.734 | J4: =I4*(1+Dashboard!$I$1) -> 24.3542 | K4: =J4-I4 -> 5.6202 | L4: =K4/J4 -> 0.23076923 | N4: =J4*B4 -> 24.3542
A5: Set01 | B5: 1 | C5: 5 | D5: 7 | E5: 4 | F5: 2.5 | G5: 5 | H5: =SUM(C5:F5)*0.09 -> 1.665 | I5: =SUM(C5:H5)*B5 -> 25.165 | J5: =I5*(1+Dashboard!$I$1) -> 32.7145 | K5: =J5-I5 -> 7.5495 | L5: =K5/J5 -> 0.23076923 | N5: =J5*B5 -> 32.7145
A6: Collection01 | B6: 1 | C6: 10 | D6: 7 | E6: 4 | F6: 2.5 | G6: 5 | H6: =SUM(C6:F6)*0.09 -> 2.115 | I6: =SUM(C6:H6)*B6 -> 30.615 | J6: =I6*(1+Dashboard!$I$1) -> 39.7995 | K6: =J6-I6 -> 9.1845 | L6: =K6/J6 -> 0.23076923 | N6: =J6*B6 -> 39.7995
C14: Cost_Type | D14: Amount
C15: Material | D15: =C6 -> 10
C16: Labor | D16: =D6 -> 7
C17: Packaging | D17: =E6 -> 4
C18: Shipping | D18: =F6 -> 2.5
C19: Fees | D19: =G6 -> 5
C20: Tax | D20: =H6 -> 2.115

Sheet Dashboard
H1: Markup %: | I1: 0.3
B2: Total Revenue | C2: =SUM(Clean_Data!J:J)*Clean_Data!M2 -> 752.6805
B3: Average Profit | C3: =AVERAGE(Clean_Data!K:K) -> 6.94782
B4: Highest Profit | C4: =MAX(Clean_Data!K:K) -> 9.1845
B5: Top Performing Product | C5: =_xlfn.XLOOKUP(C4, Clean_Data!K:K, Clean_Data!A:A) -> Collection01
B6: Avg Cost per Product | C6: =AVERAGE(Clean_Data!I:I) -> 23.1594
B7: Total Profit | C7: =SUM(Clean_Data!K:K) -> 34.7391
B8: Average Margin | C8: =AVERAGE(Clean_Data!L:L) -> 0.23076923
B55: INSIGHTS
B56: Collection01 generates the highest profit, indicating strong pricing performance
B57: Earrings01 shows lower profitability, suggesting cost or pricing inefficiencies
B58: Increasing markup improves total revenue but may impact competitiveness
B59: Cost structure (materials + labor) is the largest driver of pricing
